Workbook
Name a: #REF!
Name afg: '[1]Standard Country page'!#REF!
Name Weights: #REF!

Sheet WORKING VERSION
A1: Country | B1: Country Code (highlighted if ida-eligible country) | C1: IDA country | D1: NSDS Name | E1: NSDS Year | F1: Add URL | G1: last year | H1: last year raw | I1: needs to be checked/updated | J1: updated August 2025 (Yes/No) | K1: Is the NSDS accessible? | L1: Language (Fill in) | M1: Detailed budget available? (Yes/No) | N1: Gender data mentioned in budget (Yes/No) | O1: Are years listed in budget for gender? | P1: Gender in budget description (How is the line item for gender phrased? Entire table? Line item, other relevant descriptors) | Q1: Total gender budget number in currency of publication | R1: total gender budget currency iso code | S1: Line-item breakdown (if relevant, separated by semi-colon) | T1: Resource breakdown available for gender data or for entire plan? | U1: Domestic / External split | V1: State / Government | W1: Technical / Financial partners | X1: Other
A2: Aruba | B2: ABW | C2: =COUNTIF('IDA country list'!B$2:B$79,'WORKING VERSION'!B2) = 1 -> FALSE | D2: Not available | G2: =RIGHT(E2,4) | I2: =H2<2025 -> TRUE
A3: Afghanistan | B3: AFG | C3: =COUNTIF('IDA country list'!B$2:B$79,'WORKING VERSION'!B3) = 1 -> TRUE | I3: =H3<2025 -> TRUE | J3: TRUE
A4: Angola | B4: AGO | C4: =COUNTIF('IDA country list'!B$2:B$79,'WORKING VERSION'!B4) = 1 -> FALSE | D4: Plano Estatistico Nacional de Medio Prazo 2015-25 | E4: 2015-2025 | F4: https://www.ine.gov.ao/Arquivos/arquivosCarregados//Carregados/Publicacao_637873637947742390.pdf | G4: =RIGHT(E4,4) -> 2025 | H4: 2025 | I4: =H4<2025 -> FALSE | K4: No
A5: Anguilla | B5: AIA | C5: =COUNTIF('IDA country list'!B$2:B$79,'WORKING VERSION'!B5) = 1 -> FALSE | D5: Statistics Strategic Plan 2005-2009 | G5: =RIGHT(E5,4) | I5: =H5<2025 -> TRUE
A6: Albania | B6: ALB | C6: =COUNTIF('IDA country list'!B$2:B$79,'WORKING VERSION'!B6) = 1 -> FALSE | D6: Development Strategy of INSTAT 2017-2030 | E6: 2017-2030 | F6: http://www.instat.gov.al/media/3986/development-strategy-of-instat-2017-2030.pdf | G6: =RIGHT(E6,4) -> 2030 | H6: 2030 | I6: =H6<2025 -> FALSE | K6: Yes | L6: English | M6: No
A7: Andorra | B7: AND | C7: =COUNTIF('IDA country list'!B$2:B$79,'WORKING VERSION'!B7) = 1 -> FALSE | D7: llei 13/2022, del 12 de maig, del Pla d’estadística 2022-2025 | E7: 2022-2025 | F7: https://www.consellgeneral.ad/ca/activitat-parlamentaria/lleis-aprovades/llei-13-2022-del-12-de-maig-del-pla-d2019estadistica-2022-2025 | G7: =RIGHT(E7,4) -> 2025 | H7: 2025 | I7: =H7<2025 -> FALSE
A8: United Arab Emirates | B8: ARE | C8: =COUNTIF('IDA country list'!B$2:B$79,'WORKING VERSION'!B8) = 1 -> FALSE | D8: Not available | G8: =RIGHT(E8,4) | I8: =H8<2025 -> TRUE
A9: Argentina | B9: ARG | C9: =COUNTIF('IDA country list'!B$2:B$79,'WORKING VERSION'!B9) = 1 -> FALSE | D9: Plan Estratégico 2021-2026 | E9: 2021-2026 | F9: https://www.indec.gob.ar/ftp/cuadros/menusuperior/documentos-auxiliares/plan_estrategico_INDEC_2021_2026.pdf | G9: =RIGHT(E9,4) -> 2026 | H9: 2026 | I9: =H9<2025 -> FALSE | K9: Yes | L9: Spanish | M9: No
A10: Armenia | B10: ARM | C10: =COUNTIF('IDA country list'!B$2:B$79,'WORKING VERSION'!B10) = 1 -> FALSE | D10: Five year state statistical programme 2024-2028 | E10: 2024-2028 | F10: https://www.arlis.am/DocumentView.aspx?DocID=186099 | G10: =RIGHT(E10,4) -> 2028 | H10: 2028 | I10: =H10<2025 -> FALSE | K10: Yes | M10: No
A11: Antigua and Barbuda | B11: ATG | C11: =COUNTIF('IDA country list'!B$2:B$79,'WORKING VERSION'!B11) = 1 -> FALSE | D11: Not available | G11: =RIGHT(E11,4) | I11: =H11<2025 -> TRUE
A12: Australia | B12: AUS | C12: =COUNTIF('IDA country list'!B$2:B$79,'WORKING VERSION'!B12) = 1 -> FALSE | D12: ABS Corporate Plan 2024-25 | E12: 2024-2025 | F12: https://www.abs.gov.au/about/our-organisation/corporate-reporting/abs-corporate-plan/latest-release | G12: =RIGHT(E12,4) -> 2025 | H12: 2025 | I12: =H12<2025 -> FALSE | K12: Yes | L12: English | M12: No
A13: Austria | B13: AUT | C13: =COUNTIF('IDA country list'!B$2:B$79,'WORKING VERSION'!B13) = 1 -> FALSE | D13: Statistical Work Program 2021-2024 | F13: https://www.statistik.at/fileadmin/pages/535/strategie_2025.pdf | G13: =RIGHT(E13,4) | I13: =H13<2025 -> TRUE | K13: Yes | L13: German | M13: No
A14: Azerbaijan | B14: AZE | C14: =COUNTIF('IDA country list'!B$2:B$79,'WORKING VERSION'!B14) = 1 -> FALSE | D14: State Program on Improvement of the Official Statistics in the Republic of Azerbaijan 2018-2025 | E14: 2018-2025 | F14: https://www.stat.gov.az/menu/2/state_programs/2018_2025/source/en/2018-2025_DP_ENG.pdf | G14: =RIGHT(E14,4) -> 2025 | H14: 2025 | I14: =H14<2025 -> FALSE | K14: Yes | L14: English | M14: No
A15: Burundi | B15: BDI | C15: =COUNTIF('IDA country list'!B$2:B$79,'WORKING VERSION'!B15) = 1 -> TRUE | D15: Stratégie Nationale du Développement de la Statistique 2016-2020 | E15: 2016-2020 | F15: https://isteebu.bi/wp-content/uploads/2023/01/NSDS-Burundi_Document-Principal-2.pdf | G15: =RIGHT(E15,4) -> 2020 | H15: 2020 | I15: =H15<2025 -> TRUE | K15: Yes | L15: French | M15: Yes | N15: Yes | O15: Yes: 2016-2020 | P15: Line item: Disaggregation of all statistical data by province and gender (pg. 67) | Q15: 0 | R15: FBU | S15: $0 allocated, because goal was achieved in previous NSDS implementation
A16: Belgium | B16: BEL | C16: =COUNTIF('IDA country list'!B$2:B$79,'WORKING VERSION'!B16) = 1 -> FALSE | D16: Statistisch programma 2023 | E16: 2024 | F16: https://statbel.fgov.be/sites/default/files/Over_Statbel_FR/Programme%20statistique%20Statbel%202024-20221214-NL.pdf | G16: =RIGHT(E16,4) -> 2024 | H16: 2024 | I16: =H16<2025 -> TRUE | K16: Yes | L16: Dutch | M16: No
A17: Benin | B17: BEN | C17: =COUNTIF('IDA country list'!B$2:B$79,'WORKING VERSION'!B17) = 1 -> TRUE | D17: Stratégie Nationale de Développement de la Statistique 2020-23 | E17: 2020-2023 | F17: https://afristat.org/wp-content/uploads/2022/04/1_Benin-SNDS-2020-2023.pdf | G17: =RIGHT(E17,4) -> 2023 | H17: 2023 | I17: =H17<2025 -> TRUE | J17: TRUE | K17: Yes | L17: French | M17: Yes | N17: Yes | O17: Yes: 2020 to 2023 | P17: Activity 4 under Expected Results (RA) 2.2.2: Develop the Index on Development and Gender Inequalities in Benin (IDISB) (page 78 of PDF) | Q17: 14200000 | R17: FCFA | S17: Develop the Index on Development and Gender Inequalities in Benin (IDISB): 14.2 (Million FCFA) | T17: Yes
A18: Burkina Faso | B18: BFA | C18: =COUNTIF('IDA country list'!B$2:B$79,'WORKING VERSION'!B18) = 1 -> TRUE | D18: Schéma Directeur de la Statistique 2021-2025 | E18: 2021-2025 | F18: https://www.insd.bf/sites/default/files/2022-01/SDS-2021-2025.pdf | G18: =RIGHT(E18,4) -> 2025 | H18: 2025 | I18: =H18<2025 -> FALSE | K18: Yes | L18: French | M18: Yes | N18: Yes | O18: Yes: 2021-2025 | P18: 188- Develop gender booklets for the East, Center-East and Center-South; 193- Develop gender booklets for the regions of the Boucle du Mouhoun, Cascades, Hauts-Bassins, and South West; 198- Develop gender booklets for the Sahel and Center regions north; 202- Develop the gender booklet; 310- Develop the Women and Gender Directory; 311- Develop the Women and Gender dashboard; 425- Develop the directory of offenses involving minors and women during the police investigation phase; 426- Develop the dashboard of offenses involving minors and women during the police investigation phase; 449- Collect monitoring data on [...] women's busines in the regions of Boucle du Mouhoun and the East; 483- Carry out a census of associations/NGOs involved in the social action and women's sector; 492- Carry out a study on the socio-economic conditions of women in the region; 568- Ensure the dissemination on the INSD website of DSCVM publications (Social Dashboards, Gender Booklets....; 570- Ensure the distribution on the INSD website of the publications of the DR-INSD the DSSE (Statistical Yearbooks, gender booklets...); 617- Edit the women and gender dashboard; 620 Edit the report on the census of associations/NGOs working in the social action and women's sector; 658- Edit the directory of offenses involving minors and women during the police investigation phase; 659- Edit the dashboard of offenses involving minors and women during the police investigation phase | Q18: 683400000 | R18: FCFA | S18: 188- Develop gender booklets for the East, Center-East and Center-South: 25 million FCFA 193- Develop gender booklets for the regions of the Boucle du Mouhoun, Cascades, Hauts-Bassins, and South West: 24.4 million FCFA 198- Develop gender booklets for the Sahel and Center regions north: 9.6 million FCFA 202- Develop the gender booklet: 20 million FCFA 310- Develop the Women and Gender Directory: 55.5 million FCFA 311- Develop the Women and Gender dashboard: 60.3 million FCFA 425- Develop the directory of offenses involving minors and women during the police investigation phase: 100 million FCFA 426- Develop the dashboard of offenses involving minors and women during the police investigation phase: 25 million FCFA 449- Collect monitoring data on [...] women's busines in the regions of Boucle du Mouhoun and the East: 217.9 million FCFA 483- Carry out a census of associations/NGOs involved in the social action and women's sector: 87 million FCFA 492- Carry out a study on the socio-economic conditions of women in the region: 6.3 million FCFA 568- Ensure the dissemination on the INSD website of DSCVM publications (Social Dashboards, Gender Booklets....: 0 million FCFA 570- Ensure the distribution on the INSD website of the publications of the DR-INSD the DSSE (Statistical Yearbooks, gender booklets...): 0 million FCFA 617- Edit the women and gender dashboard: 9.4 million FCFA 620 Edit the report on the census of associations/NGOs working in the social action and women's sector: 3 million FCFA 658- Edit the directory of offenses involving minors and women during the police investigation phase: 20 million FCFA 659- Edit the dashboard of offenses involving minors and women during the police investigation phase 20 million FCFA | T18: TBD
A19: Bangladesh | B19: BGD | C19: =COUNTIF('IDA country list'!B$2:B$79,'WORKING VERSION'!B19) = 1 -> TRUE | D19: National Strategy for the Development of Statistics 2013-23 | E19: 2013-2023 | F19: http://www.paris21.org/sites/default/files/Bangladesh NSDS_2013-23_Final Cabinet approved.pdf | G19: =RIGHT(E19,4) -> 2023 | H19: 2023 | I19: =H19<2025 -> TRUE | J19: TRUE | K19: Yes | L19: English | M19: Yes | N19: Yes | O19: Yes: 2015 to 2023 | P19: Three gender-focused strategic goals in budget under the demography and health wing: Strategic goal 4: Monitoring the nutritional status of child and mother; Strategic goal 5: Gender statistics; Strategic goal 6: Violence against women (VAW). Each strategic goal has 3-4 detailed progress indicators (page 83). | Q19: 384000000 | R19: BDT | S19: Monitoring the nutrition status of child and mother: 350.00 (Million Taka); Gender statistics: 4.00 (Million Taka); VAW: 30.00 (Million Taka) (page 83)
A20: Bulgaria | B20: BGR | C20: =COUNTIF('IDA country list'!B$2:B$79,'WORKING VERSION'!B20) = 1 -> FALSE | D20: Strategy for Development of the National Statistical System 2021 - 2027 | E20: 2021-2027 | F20: https://www.nsi.bg/sites/default/files/files/pages/uplf_e/Strategy2021-2027_EN.pdf | G20: =RIGHT(E20,4) -> 2027 | H20: 2027 | I20: =H20<2025 -> FALSE | K20: Yes | L20: English | M20: No
A21: Bahrain | B21: BHR | C21: =COUNTIF('IDA country list'!B$2:B$79,'WORKING VERSION'!B21) = 1 -> FALSE | D21: Open Data Policy 2019-2023 | E21: 2019-2023 | F21: https://www.iga.gov.bh/Media/Pdf-Section/National%20Digital%20Policies/Open%20Data%20Policy%20V1.3.pdf | G21: =RIGHT(E21,4) -> 2023 | H21: 2023 | I21: =H21<2025 -> TRUE | K21: Yes | L21: English | M21: No
A22: The Bahamas | B22: BHS | C22: =COUNTIF('IDA country list'!B$2:B$79,'WORKING VERSION'!B22) = 1 -> FALSE | D22: Not available | G22: =RIGHT(E22,4) | I22: =H22<2025 -> TRUE
A23: Bosnia and Herzegovina | B23: BIH | C23: =COUNTIF('IDA country list'!B$2:B$79,'WORKING VERSION'!B23) = 1 -> FALSE | D23: Strategy for development of statistics 2021 - 2024 | E23: 2021-2024 | F23: https://bhas.gov.ba/data/Dokumenti/Planovi/STATISTICKI_PROGRAM_BIH_2021_2024.pdf | G23: =RIGHT(E23,4) -> 2024 | H23: 2024 | I23: =H23<2025 -> TRUE | K23: Yes | L23: Bosnian | M23: No
A24: Belarus | B24: BLR | C24: =COUNTIF('IDA country list'!B$2:B$79,'WORKING VERSION'!B24) = 1 -> FALSE | D24: Development of State Statistics of the Republic of Belarus 2017-2022 | E24: 2017-2022 | F24: https://www.belstat.gov.by/upload-belstat/upload-belstat-pdf/o-belstate/Stategija_2022-211025-en.pdf | G24: =RIGHT(E24,4) -> 2022 | H24: 2022 | I24: =H24<2025 -> TRUE | K24: Yes | L24: English | M24: No
A25: Belize | B25: BLZ | C25: =COUNTIF('IDA country list'!B$2:B$79,'WORKING VERSION'!B25) = 1 -> TRUE | D25: Belize's Second National Strategy for the Development of Statistics | E25: 2025-2029 | F25: https://sib.org.bz/wp-content/uploads/BelizeNSDSReport.pdf | G25: =RIGHT(E25,4) -> 2029 | H25: 2029 | I25: =H25<2025 -> FALSE | J25: TRUE | K25: Yes | L25: English | M25: Yes | N25: No
A26: Bolivia | B26: BOL | C26: =COUNTIF('IDA country list'!B$2:B$79,'WORKING VERSION'!B26) = 1 -> FALSE | D26: Plan Estratgégico Institucional PEI 2021-2025 | E26: 2021-2025 | F26: https://www.ine.gob.bo/index.php/descarga/715/plan-estrategico-institucional-2021-2025/59739/pei-2021-2025-del-ine.pdf | G26: =RIGHT(E26,4) -> 2025 | H26: 2025 | I26: =H26<2025 -> FALSE | K26: Yes | L26: Spanish | M26: Yes | N26: Yes | O26: Yes: 2021 to 2025 | P26: Line item, program category code to be defined - Comprehensive Survey on the Situation of Women (EISM) (page 53) | Q26: 10002257 | R26: BOB | S26: Comprehensive Survey on the Situation of Women (EISM): 10,002,257 (Bolivian Bolivianos) | T26: No
A27: Brazil | B27: BRA | C27: =COUNTIF('IDA country list'!B$2:B$79,'WORKING VERSION'!B27) = 1 -> FALSE | D27: PLANO Estratégico 2017 - 2027 | E27: 2017 - 2027 | F27: https://www.ibge.gov.br/np_download/novoportal/documentos_institucionais/Plano_Estrategico_2017_2027.pdf | G27: =RIGHT(E27,4) -> 2027 | H27: 2027 | I27: =H27<2025 -> FALSE | K27: Yes | L27: Portuguese | M27: No
A28: Barbados | B28: BRB | C28: =COUNTIF('IDA country list'!B$2:B$79,'WORKING VERSION'!B28) = 1 -> FALSE | D28: Not available | G28: =RIGHT(E28,4) | I28: =H28<2025 -> TRUE
A29: Brunei | B29: BRN | C29: =COUNTIF('IDA country list'!B$2:B$79,'WORKING VERSION'!B29) = 1 -> FALSE | D29: Not available | G29: =RIGHT(E29,4) | I29: =H29<2025 -> TRUE
A30: Bhutan | B30: BTN | C30: =COUNTIF('IDA country list'!B$2:B$79,'WORKING VERSION'!B30) = 1 -> TRUE | D30: National Strategy for the Development of Statistics 2024-229 | E30: 2024-2029 | F30: https://www.nsb.gov.bt/resources/plans/nsds/ | G30: =RIGHT(E30,4) -> 2029 | H30: 2029 | I30: =H30<2025 -> FALSE | J30: TRUE | K30: Yes | L30: English | M30: Yes | N30: No
A31: Botswana | B31: BWA | C31: =COUNTIF('IDA country list'!B$2:B$79,'WORKING VERSION'!B31) = 1 -> FALSE | D31: Botswana Strategy for the Development of Statistics 2015 – 2020 | E31: 2015-2020 | F31: http://www.paris21.org/sites/default/files/Botswana_Strategy_for_the_Development_of_Statistics__BSDS__-_2015_-_2020.pdf | G31: =RIGHT(E31,4) -> 2020 | H31: 2020 | I31: =H31<2025 -> TRUE | K31: Yes | L31: English | M31: Yes | N31: No
A32: Central African Republic | B32: CAF | C32: =COUNTIF('IDA country list'!B$2:B$79,'WORKING VERSION'!B32) = 1 -> TRUE | D32: Stratégie Nationale de développement de la statistique | E32: 2021-2025 | F32: https://afristat.org/wp-content/uploads/2022/04/6_RCA_SNDS-2021-2025-Finalisee.pdf | G32: =RIGHT(E32,4) -> 2025 | H32: 2025 | I32: =H32<2025 -> FALSE | K32: Yes | L32: French | M32: Yes | N32: Yes | O32: Yes: 2021-2025 | P32: Activity 3.1.1.1.B26: Conduct studies on target groups (children living and working on the street, child soldiers, the elderly, people with disabilities, OVC , victims of gender-based violence, etc.) (p.51); Activity 3.1.2.1: Take into account the needs for disaggregated data in the design and use of surveys and censuses. 2021-2025 (p. 52); Activity 3.1.2.2: Strengthen gender and regional data analysis (p. 52) | Q32: 337000000 | R32: FCFA | S32: Activity 3.1.1.1.B26: 250,000,000 FCFA; Activity 3.1.2.1: 21,000,000 FCFA; Activity 3.1.2.2: 66,000,000 FCFA | T32: Yes
A33: Canada | B33: CAN | C33: =COUNTIF('IDA country list'!B$2:B$79,'WORKING VERSION'!B33) = 1 -> FALSE | D33: Departmental Plan 2022–23 | E33: 2024-2025 | F33: https://www.statcan.gc.ca/en/transparency-accountability/corporate-management-reporting/departmental-plan/2024-2025 | G33: =RIGHT(E33,4) -> 2025 | H33: 2025 | I33: =H33<2025 -> FALSE | K33: Yes | L33: English | M33: No (broad budget but not broken down by activity/initiative) | N33: No | O33: Yes
A34: Switzerland | B34: CHE | C34: =COUNTIF('IDA country list'!B$2:B$79,'WORKING VERSION'!B34) = 1 -> FALSE | D34: Data Innovation Strategy 2017 | E34: 2017 | F34: https://www.bfs.admin.ch/bfs/en/home.assetdetail.3862240.html | G34: =RIGHT(E34,4) -> 2017 | H34: 2017 | I34: =H34<2025 -> TRUE | K34: Yes | L34: English | M34: No
A35: Chile | B35: CHL | C35: =COUNTIF('IDA country list'!B$2:B$79,'WORKING VERSION'!B35) = 1 -> FALSE | D35: Plan Estratégico Institucional 2018 - 2022 | E35: 2022-2026 | F35: https://www.ine.gob.cl/institutional/strategic-plan-2022-2026/strategic-objectives | G35: =RIGHT(E35,4) -> 2026 | H35: 2026 | I35: =H35<2025 -> FALSE | K35: Yes | L35: English (page translated) | M35: No
A36: China | B36: CHN | C36: =COUNTIF('IDA country list'!B$2:B$79,'WORKING VERSION'!B36) = 1 -> FALSE | D36: Not available | G36: =RIGHT(E36,4) | I36: =H36<2025 -> TRUE
A37: Cote d'Ivoire | B37: CIV | C37: =COUNTIF('IDA country list'!B$2:B$79,'WORKING VERSION'!B37) = 1 -> TRUE | D37: Stratégie nationale de développement de la statistique 2017 - 2021 | E37: 2017-2021 | F37: Not available | G37: =RIGHT(E37,4) -> 2021 | H37: 2021 | I37: =H37<2025 -> TRUE | J37: TRUE | K37: No | M37: Yes
A38: Cameroon | B38: CMR | C38: =COUNTIF('IDA country list'!B$2:B$79,'WORKING VERSION'!B38) = 1 -> TRUE | D38: Stratégie National de Développement de la Statistique (NSDS30, 2021-2030) 2021-2030 | E38: 2021-2030 | F38: https://www.afristat.org/wp-content/uploads/2023/06/SNDS30_Cameroun.pdf | G38: =RIGHT(E38,4) -> 2030 | H38: 2030 | I38: =H38<2025 -> FALSE | K38: Yes | L38: French | M38: Yes | N38: No. The strategic operation that gender is mentioned in is included, but because it is not broken down by specific sub-components, we cannot get a sense of how much budget is being devoted specifically to gender statistics activities (p.64). | O38: Yes: 2021-2025 | T38: No
A39: Congo, Dem. Rep. | B39: COD | C39: =COUNTIF('IDA country list'!B$2:B$79,'WORKING VERSION'!B39) = 1 -> TRUE | D39: Stratégie nationale de développement de la statistique 2012/13-17 | E39: 2012-2017 | F39: http://www.paris21.org/sites/default/files/DRC SNDS 2012-17.pdf | G39: =RIGHT(E39,4) -> 2017 | H39: 2017 | I39: =H39<2025 -> TRUE | J39: TRUE | K39: Yes | L39: French | M39: Yes | N39: No
A40: Congo, Rep. | B40: COG | C40: =COUNTIF('IDA country list'!B$2:B$79,'WORKING VERSION'!B40) = 1 -> TRUE | D40: Programme pluriannuel de développement de la statistique | E40: 2022-2026 | F40: https://www.afristat.org/wp-content/uploads/2023/06/SNDS_2022-2026_Congo.pdf | G40: =RIGHT(E40,4) -> 2026 | H40: 2026 | I40: =H40<2025 -> FALSE | K40: Yes | L40: French | M40: Yes | N40: Yes | O40: Yes: 2022-2026 | P40: A2O1R3: The production of gender statistics is promoted includes 3 line items - A2O1R3.1: awareness workshop on gender statistics; A2O1R3.2 development of a framework for producing gender statistics; A2O1R3.3: survey on gender-based violence (p.59) | Q40: 315000000 | R40: FCFA | S40: A2O1R3.1: 10,000,000 FCFA; A2O1R3.2: 5,000,000 FCFA; A2O1R3.3: 300,000,000 FCFA | T40: Yes
...

Sheet Gender Statistics plans
A1: country | B1: iso3c | C1: link
A2: Kenya | B2: KEN | C2: https://www.knbs.or.ke/gender-sector-statistics-plan/
A3: Ghana | B3: GHA | C3: https://www.mogcsp.gov.gh/mdocs-posts/five-year-strategic-plan-for-gender-statistics/
A4: Maldives | B4: MDV | C4: https://statisticsmaldives.gov.mv/mbs/wp-content/uploads/2024/10/NSDGS.pdf
A5: Dominican Republic | B5: DOM | C5: https://www.one.gob.do/publicaciones/2022/estrategia-de-estadisticas-de-genero-de-la-republica-dominicana-2021-2024/
A6: Paraguay | B6: PRY | C6: https://www.ine.gov.py/resumen/175/estrategia-de-estadisticas-de-genero-paraguay-2021--2025
A7: Georgia | B7: GEO | C7: https://www.geostat.ge/en/modules/categories/716/strategy-for-gender-statistics-2021-2023
A8: Southern Africa Development Community | B8: SADC | C8: https://www.sadc.int/sites/default/files/2024-02/SADC%20Gender%20Statistics%20Strategy%202022-30_EN.pdf
A9: Pacific Community | B9: PAC | C9: https://data.unwomen.org/sites/default/files/documents/Publications/Pacific-Roadmap-Gender-Statistics.pdf

Sheet IDA country list
A1: country | B1: Code | C1: Region | D1: Income group | E1: Lending category
A2: Afghanistan | B2: AFG | C2: Middle East, North Africa, Afghanistan & Pakistan | D2: Low income | E2: IDA | J2: AFG | K2: =J2=H2 -> FALSE | N2: BGD
A3: Bangladesh | B3: BGD | C3: South Asia | D3: Lower middle income | E3: IDA | H3: BDI | J3: BDI | K3: =J3=H3 -> TRUE | N3: BLZ
A4: Belize | B4: BLZ | C4: Latin America & Caribbean | D4: Upper middle income | E4: Blend | H4: BEN | J4: BEN | K4: =J4=H4 -> TRUE | N4: BEN
A5: Benin | B5: BEN | C5: Sub-Saharan Africa | D5: Lower middle income | E5: IDA | H5: BFA | J5: BFA | K5: =J5=H5 -> TRUE | N5: BTN
A6: Bhutan | B6: BTN | C6: South Asia | D6: Lower middle income | E6: IDA | H6: BGD | J6: BGD | K6: =J6=H6 -> TRUE | N6: BFA
A7: Burkina Faso | B7: BFA | C7: Sub-Saharan Africa | D7: Low income | E7: IDA | H7: BLZ | J7: BLZ | K7: =J7=H7 -> TRUE | N7: BDI
A8: Burundi | B8: BDI | C8: Sub-Saharan Africa | D8: Low income | E8: IDA | H8: BTN | J8: BTN | K8: =J8=H8 -> TRUE | N8: CPV
A9: Cabo Verde | B9: CPV | C9: Sub-Saharan Africa | D9: Upper middle income | E9: Blend | H9: CAF | J9: CAF | K9: =J9=H9 -> TRUE | N9: KHM
A10: Cambodia | B10: KHM | C10: East Asia & Pacific | D10: Lower middle income | E10: IDA | H10: CIV | J10: CIV | K10: =J10=H10 -> TRUE | N10: CMR
A11: Cameroon | B11: CMR | C11: Sub-Saharan Africa | D11: Lower middle income | E11: Blend | H11: CMR | J11: CMR | K11: =J11=H11 -> TRUE | N11: CAF
A12: Central African Republic | B12: CAF | C12: Sub-Saharan Africa | D12: Low income | E12: IDA | H12: COD | J12: COD | K12: =J12=H12 -> TRUE | N12: TCD
A13: Chad | B13: TCD | C13: Sub-Saharan Africa | D13: Low income | E13: IDA | H13: COG | J13: COG | K13: =J13=H13 -> TRUE | N13: COD
A14: Comoros | B14: COM | C14: Sub-Saharan Africa | D14: Lower middle income | E14: IDA | J14: COM | K14: =J14=H14 -> FALSE | N14: COG
A15: Congo, Dem. Rep. | B15: COD | C15: Sub-Saharan Africa | D15: Low income | E15: IDA | H15: CPV | J15: CPV | K15: =J15=H15 -> TRUE | N15: CIV
A16: Congo, Rep. | B16: COG | C16: Sub-Saharan Africa | D16: Lower middle income | E16: Blend | H16: DJI | J16: DJI | K16: =J16=H16 -> TRUE | N16: DJI
A17: Côte d’Ivoire | B17: CIV | C17: Sub-Saharan Africa | D17: Lower middle income | E17: Blend | H17: DMA | J17: DMA | K17: =J17=H17 -> TRUE | N17: DMA
A18: Djibouti | B18: DJI | C18: Middle East, North Africa, Afghanistan & Pakistan | D18: Lower middle income | E18: IDA | J18: ERI | K18: =J18=H18 -> FALSE | N18: SWZ
A19: Dominica | B19: DMA | C19: Latin America & Caribbean | D19: Upper middle income | E19: Blend | H19: ETH | J19: ETH | K19: =J19=H19 -> TRUE | N19: ETH
A20: Eritrea | B20: ERI | C20: Sub-Saharan Africa | D20: Low income | E20: IDA | H20: FJI | J20: FJI | K20: =J20=H20 -> TRUE | N20: FJI
A21: Eswatini | B21: SWZ | C21: Sub-Saharan Africa | D21: Lower middle income | E21: Blend | H21: FSM | J21: FSM | K21: =J21=H21 -> TRUE | N21: GHA
A22: Ethiopia | B22: ETH | C22: Sub-Saharan Africa | E22: IDA | H22: GHA | J22: GHA | K22: =J22=H22 -> TRUE | N22: GRD
A23: Fiji | B23: FJI | C23: East Asia & Pacific | D23: Upper middle income | E23: Blend | H23: GIN | J23: GIN | K23: =J23=H23 -> TRUE | N23: GIN
A24: Gambia, The | B24: GMB | C24: Sub-Saharan Africa | D24: Low income | E24: IDA | H24: GMB | J24: GMB | K24: =J24=H24 -> TRUE | N24: GNB
A25: Ghana | B25: GHA | C25: Sub-Saharan Africa | D25: Lower middle income | E25: IDA | H25: GNB | J25: GNB | K25: =J25=H25 -> TRUE | N25: GUY
A26: Grenada | B26: GRD | C26: Latin America & Caribbean | D26: Upper middle income | E26: Blend | H26: GRD | J26: GRD | K26: =J26=H26 -> TRUE | N26: HTI
A27: Guinea | B27: GIN | C27: Sub-Saharan Africa | D27: Lower middle income | E27: IDA | H27: GUY | J27: GUY | K27: =J27=H27 -> TRUE | N27: HND
A28: Guinea-Bissau | B28: GNB | C28: Sub-Saharan Africa | D28: Low income | E28: IDA | H28: HND | J28: HND | K28: =J28=H28 -> TRUE | N28: KEN
A29: Guyana | B29: GUY | C29: Latin America & Caribbean | D29: High income | E29: IDA | H29: HTI | J29: HTI | K29: =J29=H29 -> TRUE | N29: KIR
A30: Haiti | B30: HTI | C30: Latin America & Caribbean | D30: Lower middle income | E30: IDA | H30: KEN | J30: KEN | K30: =J30=H30 -> TRUE | N30: XKX
A31: Honduras | B31: HND | C31: Latin America & Caribbean | D31: Lower middle income | E31: IDA | H31: KGZ | J31: KGZ | K31: =J31=H31 -> TRUE | N31: KGZ
A32: Kenya | B32: KEN | C32: Sub-Saharan Africa | D32: Lower middle income | E32: Blend | H32: KHM | J32: KHM | K32: =J32=H32 -> TRUE | N32: LAO
A33: Kiribati | B33: KIR | C33: East Asia & Pacific | D33: Lower middle income | E33: IDA | H33: KIR | J33: KIR | K33: =J33=H33 -> TRUE | N33: LSO
A34: Kosovo | B34: XKX | C34: Europe & Central Asia | D34: Upper middle income | E34: IDA | H34: LAO | J34: LAO | K34: =J34=H34 -> TRUE | N34: LBR
... A53: Papua New Guinea | B53: PNG | C53: East Asia & Pacific | D53: Lower middle income | E53: Blend | H53: RWA | J53: RWA | K53: =J53=H53 -> TRUE | N53: SEN
A54: Rwanda | B54: RWA | C54: Sub-Saharan Africa | D54: Low income | E54: IDA | J54: SDN | K54: =J54=H54 -> FALSE | N54: SLE
A55: Samoa | B55: WSM | C55: East Asia & Pacific | D55: Upper middle income | E55: IDA | H55: SEN | J55: SEN | K55: =J55=H55 -> TRUE | N55: SLB
A56: São Tomé and Príncipe | B56: STP | C56: Sub-Saharan Africa | D56: Lower middle income | E56: IDA | H56: SLB | J56: SLB | K56: =J56=H56 -> TRUE | N56: SOM
A57: Senegal | B57: SEN | C57: Sub-Saharan Africa | D57: Lower middle income | E57: IDA | H57: SLE | J57: SLE | K57: =J57=H57 -> TRUE | N57: SSD
A58: Sierra Leone | B58: SLE | C58: Sub-Saharan Africa | D58: Low income | E58: IDA | H58: SOM | J58: SOM | K58: =J58=H58 -> TRUE | N58: LKA
...
