Workbook

Sheet NSDS Status (Consolidated)
A1: NSDS Status — Consolidated & Updated (base: PARIS21 NSDS Summary Table 2024)
A2: Sources: PARIS21 NSDS Summary Table (Jan 2026) where available; manual web checks (May 2026) for countries dropped from PARIS21's 2026 edition. '*' = non-IDA country in the original PARIS21 table.
A3: Region | B3: Country | C3: NSDS in 2024 table | D3: 2024 range | E3: Most current NSDS | F3: Current range | G3: Current status | H3: Covers 2026? | I3: Category | J3: Source | K3: Notes
A4: Africa | B4: Algeria* | C4: SNDS | D4: — | E4: SNDS | F4: — | G4: Completed/awaiting adoption; status unclear | H4: Unclear | I4: Other / status unclear | J4: PARIS21 NSDS table, Jan 2026 | K4: No range or clear status in either table
A5: Africa | B5: Angola* | C5: Plano Estatístico Nacional de Médio Prazo | D5: 2015–2025 | E5: National Strategy for the Development of Statistics | F5: 2015–2025 | G5: Implementing — due for end evaluation & update | H5: No | I5: Expired/expiring — no successor | J5: PARIS21 NSDS table, Jan 2026
A6: Africa | B6: Benin | C6: SNDS-3 | D6: 2020–2023 | E6: Stratégie Nationale de Développement de la Statistique | F6: 2021–2025 | G6: Implementing — due for end evaluation & update | H6: No | I6: Expired/expiring — no successor | J6: PARIS21 NSDS table, Jan 2026 | K6: 2026 table shows range 2021–2023/25
A7: Africa | B7: Botswana* | C7: Transitional Statistics Botswana Strategic Plan | D7: 2023–2024 | E7: Botswana Strategy for the Development of Statistics (BSDS) | F7: 2026–2030 | G7: Finalised and implementing | H7: Yes | I7: Newer NSDS adopted | J7: PARIS21 NSDS table, Jan 2026
A8: Africa | B8: Burkina Faso | C8: Schéma Directeur de la Statistique | D8: 2021–2025 | E8: Schéma Directeur de la Statistique (SDS) | F8: 2026–2030 | G8: Finalised and implementing | H8: Yes | I8: Newer NSDS adopted | J8: PARIS21 NSDS table, Jan 2026
A9: Africa | B9: Burundi | C9: SNDS | D9: 2022–2026 | E9: SNDS | F9: 2022–2026 | G9: Implementing — evaluation due 2026 | H9: Yes | I9: Still current (covers 2026) | J9: PARIS21 NSDS table, Jan 2026
A10: Africa | B10: Cabo Verde | C10: ENDE | D10: 2022–2026 | E10: SNDS | F10: 2022–2026 | G10: Implementing — evaluation due 2026 | H10: Yes | I10: Still current (covers 2026) | J10: PARIS21 NSDS table, Jan 2026
A11: Africa | B11: Cameroon | C11: SNDS30 | D11: 2021–2030 | E11: SNDS | F11: 2021–2030 | G11: Implementing — mid-term review due | H11: Yes | I11: Still current (covers 2026) | J11: PARIS21 NSDS table, Jan 2026
A12: Africa | B12: Central African Republic | C12: SNDS | D12: 2021–2025 | E12: SNDS | F12: 2021–2025 | G12: Implementing — due for end evaluation & update | H12: No | I12: Expired/expiring — no successor | J12: PARIS21 NSDS table, Jan 2026
A13: Africa | B13: Chad | C13: SNDS2 | D13: 2022–2026 | E13: SNDS | F13: 2022–2026 | G13: Implementing — evaluation due 2026 | H13: Yes | I13: Still current (covers 2026) | J13: PARIS21 NSDS table, Jan 2026
A14: Africa | B14: Comoros | C14: SNDS | D14: 2015–2019 | E14: SNDS | F14: 2026–2030 | G14: NSDS finalised | H14: Yes | I14: Newer NSDS adopted | J14: PARIS21 NSDS table, Jan 2026
A15: Africa | B15: Congo, Rep. | C15: SNDS | D15: 2022–2026 | E15: SNDS | F15: 2022–2026 | G15: Implementing — evaluation due 2026 | H15: Yes | I15: Still current (covers 2026) | J15: PARIS21 NSDS table, Jan 2026
A16: Africa | B16: Congo, Dem. Rep. | C16: SNDS | D16: 2012/13–2017 | E16: SNDS | F16: 2012/13–2017 | G16: Expired | H16: No | I16: Expired/expiring — no successor | J16: PARIS21 NSDS table, Jan 2026
A17: Africa | B17: Côte d'Ivoire | C17: SNDS | D17: 2017–2021 | E17: SNDS | F17: 2026–2030 | G17: Designing | H17: Pending | I17: New NSDS in design/pending | J17: PARIS21 NSDS table, Jan 2026 | K17: Will cover 2026 once adopted
A18: Africa | B18: Djibouti | C18: SNDS | D18: 2018–2022 | E18: SNDS | F18: 2025–2029 | G18: Implementing — mid-term review due | H18: Yes | I18: Newer NSDS adopted | J18: PARIS21 NSDS table, Jan 2026
A19: Africa | B19: Egypt* | C19: National Strategy for the Development of Statistics | D19: 2017–2021 | E19: National Strategy of Statistics | F19: 2017–2021 | G19: Expired | H19: No | I19: Expired/expiring — no successor | J19: PARIS21 NSDS table, Jan 2026 | K19: 2024 table noted 'being finalised'
A20: Africa | B20: Equatorial Guinea* | C20: SNDS | D20: 2022–2026 | E20: SNDS | F20: 2022–2026 | G20: Implementing — evaluation due 2026 | H20: Yes | I20: Still current (covers 2026) | J20: PARIS21 NSDS table, Jan 2026
A21: Africa | B21: Eritrea | C21: Master plan for development economics statistics | D21: 2010–2014 | E21: Statistical Master Plan | F21: 2023–2026 | G21: Implementing — mid-term review due | H21: Yes | I21: Newer NSDS adopted | J21: PARIS21 NSDS table, Jan 2026
A22: Africa | B22: Ethiopia | C22: Ethiopian Statistical Development Program | D22: 2023/24–2025/26 | E22: National Strategy for the Development of Statistics | F22: 2021–2026 | G22: Implementing — evaluation due 2026 | H22: Yes | I22: Still current (covers 2026) | J22: PARIS21 NSDS table, Jan 2026
A23: Africa | B23: Gabon* | C23: (unnamed) | D23: 2016–2019 | E23: SNDS | F23: 2023–2025 | G23: Implementing — due for end evaluation & update | H23: No | I23: Newer NSDS adopted | J23: PARIS21 NSDS table, Jan 2026 | K23: Newer than 2024 entry but itself now expiring
A24: Africa | B24: Gambia | C24: NSDS III | D24: 2024–2028 | E24: National Strategy for the Development of Statistics | F24: 2024–2028 | G24: Implementing — mid-term review due | H24: Yes | I24: Still current (covers 2026) | J24: PARIS21 NSDS table, Jan 2026
A25: Africa | B25: Ghana | C25: Ghana Statistical Service Corporate Plan | D25: 2020–2024 | E25: (new NSDS being designed) | F25: — | G25: Designing | H25: No | I25: New NSDS in design/pending | J25: PARIS21 NSDS table, Jan 2026 | K25: 2026 table still references a 2018–2022 NSDS
A26: Africa | B26: Guinea | C26: SNDS | D26: 2021–2025 | E26: SNDS | F26: 2021–2025 | G26: Implementing — due for end evaluation & update | H26: No | I26: Expired/expiring — no successor | J26: PARIS21 NSDS table, Jan 2026
A27: Africa | B27: Guinea-Bissau | C27: ENDE | D27: 2021–2024 | E27: ENDE | F27: 2021–2024 | G27: Implementing — due for end evaluation & update | H27: No | I27: Expired/expiring — no successor | J27: PARIS21 NSDS table, Jan 2026
A28: Africa | B28: Kenya | C28: National Strategy for the Development of Statistics | D28: 2023–2027 | E28: Kenya Strategy for Development of Statistics (KSDS) | F28: 2023–2028 | G28: Implementing — mid-term review due | H28: Yes | I28: Still current (covers 2026) | J28: PARIS21 NSDS table, Jan 2026
A29: Africa | B29: Lesotho | C29: National Strategy for the Development of Statistics | D29: 2021/22–2025/26 | E29: National Strategy for the Development of Statistics | F29: 2022–2027 | G29: Implementing — mid-term review due | H29: Yes | I29: Still current (covers 2026) | J29: PARIS21 NSDS table, Jan 2026
A30: Africa | B30: Liberia | C30: National Strategy for the Development of Statistics | D30: 2018–2022 | E30: National Strategy for the Development of Statistics | F30: — | G30: Designing | H30: No | I30: New NSDS in design/pending | J30: PARIS21 NSDS table, Jan 2026
A31: Africa | B31: Libya* | C31: National Strategy for the Development of Statistics | D31: 2018–2023 | E31: National Statistics Development Strategy | F31: 2018–2023 | G31: Implementing — due for end evaluation & update | H31: No | I31: Expired/expiring — no successor | J31: PARIS21 NSDS table, Jan 2026
A32: Africa | B32: Madagascar | C32: Deuxième SNDS | D32: 2023–2030 | E32: SNDS | F32: 2023–2030 | G32: Implementing — mid-term review due | H32: Yes | I32: Still current (covers 2026) | J32: PARIS21 NSDS table, Jan 2026
A33: Africa | B33: Malawi | C33: National Statistical System Strategic Plan | D33: 2019–2023 | E33: National Statistical System Strategic Plan | F33: 2026–2030 | G33: Finalised and implementing | H33: Yes | I33: Newer NSDS adopted | J33: PARIS21 NSDS table, Jan 2026
A34: Africa | B34: Mali | C34: Schéma Directeur de la Statistique (NSP-3) | D34: 2020–2024 | E34: Schéma Directeur de la Statistique | F34: 2026–2030 | G34: Finalised and implementing | H34: Yes | I34: Newer NSDS adopted | J34: PARIS21 NSDS table, Jan 2026
A35: Africa | B35: Mauritania | C35: SNDDS + Plan d'Actions | D35: 2021–2030 | E35: Stratégie Nationale Décennale pour le Développement de la Statistique (SNDDS) | F35: 2021–2023 | G35: Implementing — due for end evaluation & update | H35: Yes | I35: Discrepancy — verify | J35: PARIS21 NSDS table, Jan 2026 | K35: 2024 table: decennial to 2030; 2026 table: 2021–2023 — verify
A36: Africa | B36: Mauritius* | C36: Strategy for Official Statistics | D36: 2020–2025 | E36: Strategy for Official Statistics | F36: 2020–2025 | G36: Implementing — due for end evaluation & update | H36: No | I36: Expired/expiring — no successor | J36: PARIS21 NSDS table, Jan 2026
A37: Africa | B37: Morocco* | C37: Plan d'action à long terme de la Direction de la Statistique | D37: — | E37: Plan d'action à long terme de la Direction de la Statistique | F37: — | G37: Expired | H37: No | I37: Expired/expiring — no successor | J37: PARIS21 NSDS table, Jan 2026
A38: Africa | B38: Mozambique | C38: Strategic Plan of the National Statistical System | D38: 2020–2024 | E38: National Strategy for the Development of Statistics | F38: 2025–2029 | G38: Finalised and implementing | H38: Yes | I38: Newer NSDS adopted | J38: PARIS21 NSDS table, Jan 2026
A39: Africa | B39: Namibia* | C39: NSA Strategic Plan | D39: 2022/23–2026/27 | E39: National Strategy for the Development of Statistics | F39: 2023–2027 | G39: Implementing — mid-term review due | H39: Yes | I39: Still current (covers 2026) | J39: PARIS21 NSDS table, Jan 2026
A40: Africa | B40: Niger | C40: SNDS | D40: 2022–2026 | E40: SNDS | F40: 2022–2026 | G40: Implementing — evaluation due 2026 | H40: Yes | I40: Still current (covers 2026) | J40: PARIS21 NSDS table, Jan 2026
...

Sheet Summary
A1: Summary — NSDS status vs the 2024 PARIS21 table
A3: Category | B3: Count | C3: Share
A4: Newer NSDS adopted | B4: =COUNTIF('NSDS Status (Consolidated)'!I$4:I$123,A4) -> 27 | C4: =B4/$B$12 -> 0.225
A5: New NSDS in design/pending | B5: =COUNTIF('NSDS Status (Consolidated)'!I$4:I$123,A5) -> 8 | C5: =B5/$B$12 -> 0.066666667
A6: Still current (covers 2026) | B6: =COUNTIF('NSDS Status (Consolidated)'!I$4:I$123,A6) -> 29 | C6: =B6/$B$12 -> 0.24166667
A7: Expired/expiring — no successor | B7: =COUNTIF('NSDS Status (Consolidated)'!I$4:I$123,A7) -> 36 | C7: =B7/$B$12 -> 0.3
A8: No strategy | B8: =COUNTIF('NSDS Status (Consolidated)'!I$4:I$123,A8) -> 14 | C8: =B8/$B$12 -> 0.11666667
A9: Discrepancy — verify | B9: =COUNTIF('NSDS Status (Consolidated)'!I$4:I$123,A9) -> 3 | C9: =B9/$B$12 -> 0.025
A10: Other / status updated | B10: =COUNTIF('NSDS Status (Consolidated)'!I$4:I$123,A10) -> 2 | C10: =B10/$B$12 -> 0.016666667
A11: Other / status unclear | B11: =COUNTIF('NSDS Status (Consolidated)'!I$4:I$123,A11) -> 1 | C11: =B11/$B$12 -> 0.0083333333
A12: TOTAL | B12: =SUM(B4:B11) -> 120 | C12: =SUM(C4:C11) -> 1
A14: Covers 2026? | B14: Count
A15: Yes | B15: =COUNTIF('NSDS Status (Consolidated)'!H$4:H$123,A15) -> 53
A16: No | B16: =COUNTIF('NSDS Status (Consolidated)'!H$4:H$123,A16) -> 60
A17: Pending | B17: =COUNTIF('NSDS Status (Consolidated)'!H$4:H$123,A17) -> 2
A18: Unclear | B18: =COUNTIF('NSDS Status (Consolidated)'!H$4:H$123,A18) -> 5
A20: Method: Each country from the 2024 PARIS21 NSDS Summary Table was checked against PARIS21's January 2026 table. The ~23 countries PARIS21 dropped from the 2026 edition were verified via individual web searches in May 2026. 'Newer NSDS adopted' = a more recent strategy than the 2024 entry. 'Discrepancy — verify' = the 2024 and 2026 PARIS21 tables conflict. Entries marked '—' had no name/range available in the source.
